Workbook

Sheet Project_Overview
A1: Project | B1: ISO 27001 Compliance Gap Assessment & Risk Register Dashboard
A2: Simulated Organization | B2: Northstar Digital Services Pvt. Ltd.
A3: Assessment Date | B3: 46213
A4: Purpose | B4: Demonstrate a practical GRC workflow for assessing selected ISO/IEC 27001:2022 Annex A controls, documenting gaps, evaluating risks and tracking remediation.
A5: Assessment Scope | B5: 40 representative controls across Organizational, People, Physical and Technological themes.
A6: Assessment Type | B6: Portfolio simulation; not a certification audit, conformity assessment or statement of ISO certification.
A7: Risk Methodology | B7: Inherent Risk Score = Likelihood × Impact, using a 1–5 scale. Risk bands are defined in the Lookup_Lists sheet.
A8: Evidence Principle | B8: Assessment results are based on simulated evidence references created for this portfolio project.
A9: Build Status | B9: Excel phase complete. Power BI dashboard is the next phase.
A10: Workbook Flow | B10: Control_Master → Gap_Assessment → Risk_Register → Remediation_Tracker → Power BI

Sheet Management_Summary
A1: Metric | B1: Value | C1: Definition
A2: Total Controls | B2: 40 | C2: Finalized representative control universe assessed.
A3: Implemented Controls | B3: =COUNTIF(Gap_Assessment!F:F,"Implemented") -> 18 | C3: Controls assessed as fully implemented.
A4: Partially Implemented Controls | B4: =COUNTIF(Gap_Assessment!F:F,"Partially Implemented") -> 20 | C4: Controls with evidence but material improvement needed.
A5: Not Implemented Controls | B5: =COUNTIF(Gap_Assessment!F:F,"Not Implemented") -> 2 | C5: Controls without an established implementation.
A6: Not Applicable Controls | B6: =COUNTIF(Gap_Assessment!F:F,"Not Applicable") -> 0 | C6: Controls determined not applicable; none used in this simulation.
A7: Overall Compliance Score | B7: =(B3*1+B4*0.5+B5*0)/B2 -> 0.7 | C7: Weighted portfolio score: Implemented = 100%, Partial = 50%, Not Implemented = 0%.
A8: Total Risks | B8: 13 | C8: Risks entered into the risk register from significant gaps.
A9: Critical Risks | B9: =COUNTIF(Risk_Register!K:K,"Critical") -> 6 | C9: Risks with inherent score 17–25.
A10: High Risks | B10: =COUNTIF(Risk_Register!K:K,"High") -> 7 | C10: Risks with inherent score 10–16.
A11: Medium Risks | B11: =COUNTIF(Risk_Register!K:K,"Medium") -> 0 | C11: Risks with inherent score 5–9.
A12: Low Risks | B12: =COUNTIF(Risk_Register!K:K,"Low") -> 0 | C12: Risks with inherent score 1–4.
A13: Open Remediation Actions | B13: =COUNTIF(Remediation_Tracker!J:J,"<>Completed")-1-COUNTIF(Remediation_Tracker!J:J,"Accepted") -> 1048575 | C13: Actions not yet completed or accepted.
A14: Average Remediation Completion | B14: =AVERAGE(Remediation_Tracker!K:K)/100 -> 0.15384615 | C14: Average completion percentage across remediation actions.

Sheet Control_Master
A1: Control_ID | B1: Control_Category | C1: Control_Name | D1: Control_Objective | E1: Assessment_Criteria | F1: Evidence_Required | G1: Applicable
A2: A.5.1 | B2: Organizational | C2: Policies for information security | D2: Establish, approve, communicate and periodically review information security policies. | E2: Verify approved policy documents, version history, review evidence and communication records. | F2: Approved information security policy; review record; communication evidence | G2: Yes
A3: A.5.2 | B3: Organizational | C3: Information security roles and responsibilities | D3: Define and assign information security responsibilities and accountability. | E3: Check role descriptions, RACI/assignment records and management approvals. | F3: RACI matrix; job descriptions; responsibility assignments | G3: Yes
A4: A.5.4 | B4: Organizational | C4: Management responsibilities | D4: Ensure management establishes and supports information security responsibilities and practices. | E4: Verify management directives, approvals, reviews and evidence of security responsibilities. | F4: Management approvals; meeting minutes; directives | G4: Yes
A5: A.5.7 | B5: Organizational | C5: Threat intelligence | D5: Collect and use relevant threat information to support information security decisions. | E5: Check whether threat information is sourced, reviewed and used in risk or security decisions. | F5: Threat reports; intelligence subscriptions; review records | G5: Yes
A6: A.5.9 | B6: Organizational | C6: Inventory of information and other associated assets | D6: Maintain an appropriate inventory of information and associated assets. | E6: Verify asset inventory completeness, ownership, classification and review frequency. | F6: Asset register; ownership records; review evidence | G6: Yes
A7: A.5.10 | B7: Organizational | C7: Acceptable use of information and other associated assets | D7: Define acceptable use and handling expectations for organizational information and assets. | E7: Check approved acceptable-use requirements and evidence that users acknowledge them. | F7: Acceptable-use policy; acknowledgements; training records | G7: Yes
A8: A.5.12 | B8: Organizational | C8: Classification of information | D8: Classify information according to organizational security needs. | E8: Verify classification scheme, assigned classifications and handling rules. | F8: Classification policy; sample classified records; handling rules | G8: Yes
A9: A.5.14 | B9: Organizational | C9: Information transfer | D9: Protect information during transfer using defined requirements and approved methods. | E9: Check transfer procedures, approved channels and safeguards for sensitive information. | F9: Transfer procedure; secure-transfer configuration; agreements | G9: Yes
A10: A.5.15 | B10: Organizational | C10: Access control | D10: Establish rules governing logical and physical access to information and associated assets. | E10: Verify access-control policy, authorization rules and periodic review mechanisms. | F10: Access-control policy; authorization records; review reports | G10: Yes
A11: A.5.16 | B11: Organizational | C11: Identity management | D11: Manage identities throughout their lifecycle. | E11: Check joiner/mover/leaver processes, unique identities and lifecycle controls. | F11: Identity lifecycle procedure; IAM records; termination samples | G11: Yes
A12: A.5.17 | B12: Organizational | C12: Authentication information | D12: Protect authentication information through defined management and handling practices. | E12: Verify password/authentication requirements and secure handling procedures. | F12: Authentication policy; configuration evidence; procedures | G12: Yes
... A41: A.8.16 | B41: Technological | C41: Monitoring activities | D41: Monitor systems and networks for relevant anomalies and security events. | E41: Verify monitoring coverage, alert handling, escalation and review. | F41: SIEM/monitoring reports; alert tickets; escalation records | G41: Yes

Sheet Gap_Assessment
A1: Assessment_ID | B1: Control_ID | C1: Control_Category | D1: Control_Name | E1: Assessment_Date | F1: Status | G1: Maturity | H1: Evidence_Available | I1: Evidence_Reference | J1: Gap_Description | K1: Assessor_Notes | L1: Gap_Owner | M1: Priority
A2: GA-001 | B2: A.5.1 | C2: Organizational | D2: Policies for information security | E2: 46213 | F2: Implemented | G2: Defined / Operating | H2: Yes | I2: ISMS-POL-001 v2.1 | K2: Policy approved by management and reviewed in June 2026. | L2: Information Security | M2: Low
A3: GA-002 | B3: A.5.2 | C3: Organizational | D3: Information security roles and responsibilities | E3: 46213 | F3: Implemented | G3: Defined / Operating | H3: Yes | I3: ISMS-RACI-001 | K3: Security roles are assigned across IT, HR, Legal and management. | L3: Information Security | M3: Low
A4: GA-003 | B4: A.5.4 | C4: Organizational | D4: Management responsibilities | E4: 46213 | F4: Implemented | G4: Defined / Operating | H4: Yes | I4: MGMT-MIN-014 | K4: Management reviews security responsibilities during quarterly governance meetings. | L4: Information Security | M4: Low
A5: GA-004 | B5: A.5.7 | C5: Organizational | D5: Threat intelligence | E5: 46213 | F5: Partially Implemented | G5: Defined / Partially Operating | H5: Partial | I5: TI-LOG-003 | J5: Formalize threat intelligence sources, review cadence and decision records. | K5: Threat feeds are reviewed by IT, but there is no documented recurring threat-intelligence review process. | L5: Information Security | M5: Medium
A6: GA-005 | B6: A.5.9 | C6: Organizational | D6: Inventory of information and other associated assets | E6: 46213 | F6: Partially Implemented | G6: Defined / Partially Operating | H6: Partial | I6: ASSET-REG-2026Q2 | J6: Expand asset inventory and establish quarterly ownership review. | K6: Hardware is inventoried, but SaaS and information assets are not consistently mapped to owners. | L6: Information Security | M6: Medium
A7: GA-006 | B7: A.5.10 | C7: Organizational | D7: Acceptable use of information and other associated assets | E7: 46213 | F7: Implemented | G7: Defined / Operating | H7: Yes | I7: AUP-001 v2.0 | K7: Acceptable-use policy is approved and acknowledged by employees. | L7: Information Security | M7: Low
A8: GA-007 | B8: A.5.12 | C8: Organizational | D8: Classification of information | E8: 46213 | F8: Partially Implemented | G8: Defined / Partially Operating | H8: Partial | I8: INFO-CLASS-001 | J8: Improve labeling guidance and perform periodic compliance checks. | K8: Classification levels exist, but sampled documents were inconsistently labeled. | L8: Information Security | M8: Medium
A9: GA-008 | B9: A.5.14 | C9: Organizational | D9: Information transfer | E9: 46213 | F9: Partially Implemented | G9: Defined / Partially Operating | H9: Partial | I9: TRN-STD-002 | J9: Standardize secure-transfer requirements in supplier workflows. | K9: Approved transfer methods exist, but supplier transfer requirements are not consistently documented. | L9: Information Security | M9: Medium
A10: GA-009 | B10: A.5.15 | C10: Organizational | D10: Access control | E10: 46213 | F10: Implemented | G10: Defined / Operating | H10: Yes | I10: ACC-POL-001 | K10: Access control policy and authorization principles are established. | L10: Information Security | M10: Low
A11: GA-010 | B11: A.5.16 | C11: Organizational | D11: Identity management | E11: 46213 | F11: Implemented | G11: Defined / Operating | H11: Yes | I11: IAM-SOP-004 | K11: Joiner/mover/leaver workflow is integrated with HR tickets. | L11: Information Security | M11: Low
A12: GA-011 | B12: A.5.17 | C12: Organizational | D12: Authentication information | E12: 46213 | F12: Implemented | G12: Defined / Operating | H12: Yes | I12: AUTH-POL-002 | K12: Authentication requirements and credential handling procedures are documented. | L12: Information Security | M12: Low
A13: GA-012 | B13: A.5.18 | C13: Organizational | D13: Access rights | E13: 46213 | F13: Partially Implemented | G13: Defined / Partially Operating | H13: Partial | I13: ACC-REV-2026Q2 | J13: Complete quarterly access certification for all critical applications. | K13: Access requests are approved, but quarterly recertification coverage is incomplete. | L13: Information Security | M13: High
A14: GA-013 | B14: A.5.19 | C14: Organizational | D14: Information security in supplier relationships | E14: 46213 | F14: Partially Implemented | G14: Defined / Partially Operating | H14: Partial | I14: SUP-SEC-REG-001 | J14: Extend risk-based supplier assessment coverage. | K14: Supplier security due diligence exists for critical vendors but not consistently for medium-risk suppliers. | L14: Information Security | M14: Medium
A15: GA-014 | B15: A.5.20 | C15: Organizational | D15: Addressing information security within supplier agreements | E15: 46213 | F15: Partially Implemented | G15: Defined / Partially Operating | H15: Partial | I15: SUP-CON-CHK-001 | J15: Refresh legacy agreements using approved security clause checklist. | K15: Security clauses are included in major supplier contracts; legacy contracts are not consistently updated. | L15: Information Security | M15: Medium
A16: GA-015 | B16: A.5.23 | C16: Organizational | D16: Information security for use of cloud services | E16: 46213 | F16: Partially Implemented | G16: Defined / Partially Operating | H16: Partial | I16: CLOUD-ASSMT-002 | J16: Document cloud exit strategy and shared-responsibility ownership. | K16: Cloud providers are assessed, but formal exit plans and configuration ownership are inconsistent. | L16: Information Security | M16: Medium
A17: GA-016 | B17: A.5.24 | C17: Organizational | D17: Information security incident management planning and preparation | E17: 46213 | F17: Implemented | G17: Defined / Operating | H17: Yes | I17: IR-PLAN-001 v3.0 | K17: Incident response plan includes roles, escalation and communications. | L17: Information Security | M17: Low
A18: GA-017 | B18: A.5.25 | C18: Organizational | D18: Assessment and decision on information security events | E18: 46213 | F18: Partially Implemented | G18: Defined / Partially Operating | H18: Partial | I18: IR-TRIAGE-001 | J18: Implement mandatory severity classification field. | K18: Events are triaged, but severity criteria are not consistently recorded in tickets. | L18: Information Security | M18: Medium
A19: GA-018 | B19: A.5.26 | C19: Organizational | D19: Response to information security incidents | E19: 46213 | F19: Implemented | G19: Defined / Operating | H19: Yes | I19: IR-REC-2026-04 | K19: Recent incident records demonstrate containment and recovery steps. | L19: Information Security | M19: Low
A20: GA-019 | B20: A.5.27 | C20: Organizational | D20: Learning from information security incidents | E20: 46213 | F20: Partially Implemented | G20: Defined / Partially Operating | H20: Partial | I20: IR-RCA-LOG-001 | J20: Standardize post-incident review criteria. | K20: Lessons learned are captured for major incidents but not consistently for low-severity incidents. | L20: Information Security | M20: Medium
A21: GA-020 | B21: A.5.30 | C21: Organizational | D21: ICT readiness for business continuity | E21: 46213 | F21: Partially Implemented | G21: Defined / Partially Operating | H21: Partial | I21: BCP-ICT-001 | J21: Expand continuity test scope to critical application dependencies. | K21: Backups and recovery arrangements exist, but not all critical application dependencies are included in continuity testing. | L21: Information Security | M21: Medium
A22: GA-021 | B22: A.5.31 | C22: Organizational | D22: Legal, statutory, regulatory and contractual requirements | E22: 46213 | F22: Implemented | G22: Defined / Operating | H22: Yes | I22: LEGAL-REG-001 | K22: Applicable legal and contractual obligations are recorded and reviewed. | L22: Information Security | M22: Low
A23: GA-022 | B23: A.5.34 | C23: Organizational | D23: Privacy and protection of PII | E23: 46213 | F23: Partially Implemented | G23: Defined / Partially Operating | H23: Partial | I23: PRIV-REG-001 | J23: Complete PII inventory and ownership mapping. | K23: PII processing is documented for major systems, but the inventory is incomplete for several SaaS tools. | L23: Information Security | M23: High
A24: GA-023 | B24: A.5.35 | C24: Organizational | D24: Independent review of information security | E24: 46213 | F24: Not Implemented | G24: Not Established | H24: No | I24: AUD-PLAN-001 | J24: Schedule an independent ISMS/security review and track findings. | K24: No independent information security review has been completed during the assessment period. | L24: Information Security | M24: Critical
A25: GA-024 | B25: A.5.36 | C25: Organizational | D25: Compliance with policies, rules and standards for information security | E25: 46213 | F25: Partially Implemented | G25: Defined / Partially Operating | H25: Partial | I25: COMP-CHECK-2026Q2 | J25: Standardize compliance evidence retention and exception tracking. | K25: Internal compliance checks are performed, but evidence retention is inconsistent. | L25: Information Security | M25: Medium
A26: GA-025 | B26: A.6.1 | C26: People | D26: Screening | E26: 46213 | F26: Implemented | G26: Defined / Operating | H26: Yes | I26: HR-SCR-001 | K26: Pre-employment screening is performed according to role requirements. | L26: HR / Information Security | M26: Low
A27: GA-026 | B27: A.6.3 | C27: People | D27: Information security awareness, education and training | E27: 46213 | F27: Implemented | G27: Defined / Operating | H27: Yes | I27: SEC-TRAIN-2026 | K27: Annual awareness training reached 96% completion; remaining users are tracked. | L27: HR / Information Security | M27: Low
A28: GA-027 | B28: A.6.5 | C28: People | D28: Responsibilities after termination or change of employment | E28: 46213 | F28: Implemented | G28: Defined / Operating | H28: Yes | I28: HR-OFF-001 | K28: Termination workflow includes access removal and continuing obligations. | L28: HR / Information Security | M28: Low
A29: GA-028 | B29: A.6.7 | C29: People | D29: Remote working | E29: 46213 | F29: Partially Implemented | G29: Defined / Partially Operating | H29: Partial | I29: REMOTE-SEC-001 | J29: Extend endpoint compliance monitoring to contractor devices. | K29: Remote work requirements exist, but endpoint compliance reporting is incomplete for contractors. | L29: HR / Information Security | M29: Medium
A30: GA-029 | B30: A.7.1 | C30: Physical | D30: Physical security perimeters | E30: 46213 | F30: Implemented | G30: Defined / Operating | H30: Yes | I30: PHY-SEC-001 | K30: Office perimeter controls and restricted-area boundaries are documented. | L30: Facilities / Security | M30: Low
A31: GA-030 | B31: A.7.2 | C31: Physical | D31: Physical entry | E31: 46213 | F31: Implemented | G31: Defined / Operating | H31: Yes | I31: PHY-ACC-LOG-2026 | K31: Badge access and visitor registration are in use. | L31: Facilities / Security | M31: Low
A32: GA-031 | B32: A.7.4 | C32: Physical | D32: Physical security monitoring | E32: 46213 | F32: Partially Implemented | G32: Defined / Partially Operating | H32: Partial | I32: CCTV-LOG-001 | J32: Document retention verification and periodic monitoring checks. | K32: CCTV covers critical areas, but retention verification is not consistently documented. | L32: Facilities / Security | M32: Medium
A33: GA-032 | B33: A.7.7 | C33: Physical | D33: Clear desk and clear screen | E33: 46213 | F33: Implemented | G33: Defined / Operating | H33: Yes | I33: CDCS-POL-001 | K33: Clear desk and clear screen requirements are communicated to staff. | L33: Facilities / Security | M33: Low
A34: GA-033 | B34: A.7.10 | C34: Physical | D34: Storage media | E34: 46213 | F34: Partially Implemented | G34: Defined / Partially Operating | H34: Partial | I34: MEDIA-REG-001 | J34: Complete media inventory and disposal evidence reconciliation. | K34: Media disposal is controlled, but older removable media records are incomplete. | L34: Facilities / Security | M34: Medium
A35: GA-034 | B35: A.8.2 | C35: Technological | D35: Privileged access rights | E35: 46213 | F35: Partially Implemented | G35: Defined / Partially Operating | H35: Partial | I35: PAM-REG-001 | J35: Complete privileged access recertification and exception review. | K35: Privileged accounts are inventoried, but quarterly recertification is incomplete. | L35: IT Security | M35: High
A36: GA-035 | B36: A.8.5 | C36: Technological | D36: Secure authentication | E36: 46213 | F36: Partially Implemented | G36: Defined / Partially Operating | H36: Partial | I36: MFA-REPORT-2026Q2 | J36: Extend MFA coverage to remaining legacy applications. | K36: MFA is enabled for major cloud services but not yet universal for legacy internal applications. | L36: IT Security | M36: High
A37: GA-036 | B37: A.8.7 | C37: Technological | D37: Protection against malware | E37: 46213 | F37: Implemented | G37: Defined / Operating | H37: Yes | I37: EDR-COV-2026Q2 | K37: Endpoint protection coverage is 99% with centralized alerting. | L37: IT Security | M37: Low
A38: GA-037 | B38: A.8.8 | C38: Technological | D38: Management of technical vulnerabilities | E38: 46213 | F38: Partially Implemented | G38: Defined / Partially Operating | H38: Partial | I38: VULN-SCAN-2026Q2 | J38: Strengthen remediation tracking and escalation for overdue vulnerabilities. | K38: Monthly scanning occurs, but some high-severity findings exceed remediation SLA. | L38: IT Security | M38: High
A39: GA-038 | B39: A.8.13 | C39: Technological | D39: Information backup | E39: 46213 | F39: Implemented | G39: Defined / Operating | H39: Yes | I39: BKP-REP-2026Q2 | K39: Critical systems are backed up and restore tests are performed. | L39: IT Security | M39: Low
A40: GA-039 | B40: A.8.15 | C40: Technological | D40: Logging | E40: 46213 | F40: Partially Implemented | G40: Defined / Partially Operating | H40: Partial | I40: LOG-STD-001 | J40: Standardize retention requirements and coverage. | K40: Central logging exists for key systems, but log retention is inconsistent across legacy applications. | L40: IT Security | M40: Medium
...

Sheet Risk_Register
A1: Risk_ID | B1: Assessment_ID | C1: Risk_Title | D1: Risk_Description | E1: Asset | F1: Threat | G1: Vulnerability | H1: Likelihood | I1: Impact | J1: Inherent_Risk_Score | K1: Inherent_Risk_Level | L1: Risk_Owner | M1: Treatment | N1: Mitigation_Action | O1: Target_Date | P1: Status | Q1: Residual_Likelihood | R1: Residual_Impact | S1: Residual_Risk_Score | T1: Residual_Risk_Level
A2: R-001 | B2: GA-004 | C2: Inadequate threat intelligence process | D2: Security decisions may not consistently incorporate current threat information. | E2: Security decision process | F2: Insufficient documented threat-intelligence review | G2: Threat intelligence not formally reviewed on a recurring basis | H2: 3 | I2: 4 | J2: =H2*I2 -> 12 | K2: =IF(J2<=4,"Low",IF(J2<=9,"Medium",IF(J2<=16,"High","Critical"))) -> High | L2: IT Security | M2: Mitigate | N2: Formalize threat intelligence sources, review cadence and decision records | O2: 2026-09-30 | P2: Open | Q2: 2 | R2: 3 | S2: =Q2*R2 -> 6 | T2: =IF(S2<=4,"Low",IF(S2<=9,"Medium",IF(S2<=16,"High","Critical"))) -> Medium
A3: R-002 | B3: GA-005 | C3: Incomplete asset inventory | D3: Untracked SaaS or information assets may remain outside security controls. | E3: Information assets / SaaS | F3: Incomplete ownership mapping | G3: SaaS and information assets are not consistently mapped to owners | H3: 4 | I3: 4 | J3: =H3*I3 -> 16 | K3: =IF(J3<=4,"Low",IF(J3<=9,"Medium",IF(J3<=16,"High","Critical"))) -> High | L3: IT Operations | M3: Mitigate | N3: Complete asset discovery and quarterly ownership certification | O3: 2026-09-20 | P3: Open | Q3: 3 | R3: 3 | S3: =Q3*R3 -> 9 | T3: =IF(S3<=4,"Low",IF(S3<=9,"Medium",IF(S3<=16,"High","Critical"))) -> Medium
A4: R-003 | B4: GA-007 | C4: Inconsistent information classification | D4: Sensitive information may receive insufficient handling protection. | E4: Business information | F4: Inconsistent labeling | G4: Sampled information was not consistently labeled | H4: 3 | I4: 4 | J4: =H4*I4 -> 12 | K4: =IF(J4<=4,"Low",IF(J4<=9,"Medium",IF(J4<=16,"High","Critical"))) -> High | L4: Information Security | M4: Mitigate | N4: Reinforce classification guidance and conduct periodic checks | O4: 2026-09-25 | P4: Open | Q4: 2 | R4: 3 | S4: =Q4*R4 -> 6 | T4: =IF(S4<=4,"Low",IF(S4<=9,"Medium",IF(S4<=16,"High","Critical"))) -> Medium
A5: R-004 | B5: GA-012 | C5: Incomplete access recertification | D5: Excess or stale access may remain active longer than necessary. | E5: Critical applications | F5: Incomplete periodic review | G5: Quarterly access recertification does not cover all critical applications | H5: 4 | I5: 5 | J5: =H5*I5 -> 20 | K5: =IF(J5<=4,"Low",IF(J5<=9,"Medium",IF(J5<=16,"High","Critical"))) -> Critical | L5: IT Security | M5: Mitigate | N5: Complete quarterly access certification for critical applications | O5: 2026-09-15 | P5: In Progress | Q5: 3 | R5: 4 | S5: =Q5*R5 -> 12 | T5: =IF(S5<=4,"Low",IF(S5<=9,"Medium",IF(S5<=16,"High","Critical"))) -> High
A6: R-005 | B6: GA-015 | C6: Weak cloud exit planning | D6: The organization may face security and continuity issues when terminating a cloud service. | E6: Cloud services | F6: Incomplete exit planning | G6: Formal cloud exit plans are inconsistent | H6: 3 | I6: 4 | J6: =H6*I6 -> 12 | K6: =IF(J6<=4,"Low",IF(J6<=9,"Medium",IF(J6<=16,"High","Critical"))) -> High | L6: IT Operations | M6: Mitigate | N6: Document exit strategy and shared-responsibility ownership | O6: 2026-10-10 | P6: Open | Q6: 2 | R6: 3 | S6: =Q6*R6 -> 6 | T6: =IF(S6<=4,"Low",IF(S6<=9,"Medium",IF(S6<=16,"High","Critical"))) -> Medium
A7: R-006 | B7: GA-017 | C7: Inconsistent incident severity classification | D7: Security incidents may not receive consistent prioritization or escalation. | E7: Incident management | F7: Inconsistent ticket classification | G7: Severity criteria are not consistently recorded | H7: 3 | I7: 4 | J7: =H7*I7 -> 12 | K7: =IF(J7<=4,"Low",IF(J7<=9,"Medium",IF(J7<=16,"High","Critical"))) -> High | L7: SOC / IT Security | M7: Mitigate | N7: Make severity classification mandatory in incident workflow | O7: 2026-09-10 | P7: In Progress | Q7: 2 | R7: 3 | S7: =Q7*R7 -> 6 | T7: =IF(S7<=4,"Low",IF(S7<=9,"Medium",IF(S7<=16,"High","Critical"))) -> Medium
A8: R-007 | B8: GA-022 | C8: Incomplete PII inventory | D8: Personal information may be processed without complete visibility of ownership and handling requirements. | E8: PII / customer information | F8: Incomplete PII mapping | G8: Several SaaS tools are missing from the PII inventory | H8: 4 | I8: 5 | J8: =H8*I8 -> 20 | K8: =IF(J8<=4,"Low",IF(J8<=9,"Medium",IF(J8<=16,"High","Critical"))) -> Critical | L8: Privacy / Legal | M8: Mitigate | N8: Complete PII inventory and ownership mapping | O8: 2026-09-30 | P8: Open | Q8: 3 | R8: 4 | S8: =Q8*R8 -> 12 | T8: =IF(S8<=4,"Low",IF(S8<=9,"Medium",IF(S8<=16,"High","Critical"))) -> High
A9: R-008 | B9: GA-023 | C9: No independent security review | D9: Control weaknesses may remain unidentified due to lack of independent challenge. | E9: ISMS / security governance | F9: No independent review | G9: No independent information security review completed in the period | H9: 3 | I9: 5 | J9: =H9*I9 -> 15 | K9: =IF(J9<=4,"Low",IF(J9<=9,"Medium",IF(J9<=16,"High","Critical"))) -> High | L9: CISO / Management | M9: Mitigate | N9: Schedule independent ISMS/security review and track findings | O9: 2026-10-15 | P9: Open | Q9: 2 | R9: 4 | S9: =Q9*R9 -> 8 | T9: =IF(S9<=4,"Low",IF(S9<=9,"Medium",IF(S9<=16,"High","Critical"))) -> Medium
A10: R-009 | B10: GA-028 | C10: Incomplete contractor endpoint visibility | D10: Unmanaged contractor devices may introduce malware or data leakage risk. | E10: Endpoint devices | F10: Incomplete compliance monitoring | G10: Endpoint compliance reporting does not fully cover contractors | H10: 3 | I10: 5 | J10: =H10*I10 -> 15 | K10: =IF(J10<=4,"Low",IF(J10<=9,"Medium",IF(J10<=16,"High","Critical"))) -> High | L10: IT Operations | M10: Mitigate | N10: Extend endpoint compliance monitoring to contractor devices | O10: 2026-09-30 | P10: Open | Q10: 2 | R10: 4 | S10: =Q10*R10 -> 8 | T10: =IF(S10<=4,"Low",IF(S10<=9,"Medium",IF(S10<=16,"High","Critical"))) -> Medium
A11: R-010 | B11: GA-034 | C11: Privileged access recertification gap | D11: Excessive privileged access may remain active, increasing compromise impact. | E11: Privileged accounts | F11: Incomplete review | G11: Quarterly privileged access recertification is incomplete | H11: 4 | I11: 5 | J11: =H11*I11 -> 20 | K11: =IF(J11<=4,"Low",IF(J11<=9,"Medium",IF(J11<=16,"High","Critical"))) -> Critical | L11: IT Security | M11: Mitigate | N11: Complete privileged access recertification and exception review | O11: 2026-09-15 | P11: In Progress | Q11: 3 | R11: 4 | S11: =Q11*R11 -> 12 | T11: =IF(S11<=4,"Low",IF(S11<=9,"Medium",IF(S11<=16,"High","Critical"))) -> High
A12: R-011 | B12: GA-035 | C12: Incomplete MFA coverage | D12: Legacy applications may be accessed with weaker authentication controls. | E12: Legacy applications | F12: MFA not universal | G12: MFA is not yet enabled for all legacy internal applications | H12: 4 | I12: 5 | J12: =H12*I12 -> 20 | K12: =IF(J12<=4,"Low",IF(J12<=9,"Medium",IF(J12<=16,"High","Critical"))) -> Critical | L12: IT Security | M12: Mitigate | N12: Extend MFA to remaining legacy applications | O12: 2026-10-01 | P12: Open | Q12: 3 | R12: 4 | S12: =Q12*R12 -> 12 | T12: =IF(S12<=4,"Low",IF(S12<=9,"Medium",IF(S12<=16,"High","Critical"))) -> High
A13: R-012 | B13: GA-037 | C13: Overdue vulnerability remediation | D13: Known vulnerabilities may remain exploitable beyond defined remediation expectations. | E13: IT infrastructure | F13: Remediation SLA breach | G13: Some high-severity vulnerabilities exceed remediation SLA | H13: 4 | I13: 5 | J13: =H13*I13 -> 20 | K13: =IF(J13<=4,"Low",IF(J13<=9,"Medium",IF(J13<=16,"High","Critical"))) -> Critical | L13: IT Operations | M13: Mitigate | N13: Escalate overdue high-severity vulnerabilities and track exceptions | O13: 2026-08-31 | P13: In Progress | Q13: 3 | R13: 4 | S13: =Q13*R13 -> 12 | T13: =IF(S13<=4,"Low",IF(S13<=9,"Medium",IF(S13<=16,"High","Critical"))) -> High
A14: R-013 | B14: GA-040 | C14: Insufficient centralized monitoring | D14: Security events in critical systems may not be detected promptly. | E14: Critical systems | F14: Monitoring coverage gap | G14: Several critical systems lack centralized monitoring and alert escalation | H14: 4 | I14: 5 | J14: =H14*I14 -> 20 | K14: =IF(J14<=4,"Low",IF(J14<=9,"Medium",IF(J14<=16,"High","Critical"))) -> Critical | L14: IT Security | M14: Mitigate | N14: Implement centralized monitoring for critical systems | O14: 2026-11-15 | P14: Open | Q14: 3 | R14: 4 | S14: =Q14*R14 -> 12 | T14: =IF(S14<=4,"Low",IF(S14<=9,"Medium",IF(S14<=16,"High","Critical"))) -> High

Sheet Remediation_Tracker
A1: Action_ID | B1: Risk_ID | C1: Assessment_ID | D1: Gap | E1: Remediation_Action | F1: Owner | G1: Priority | H1: Start_Date | I1: Target_Date | J1: Status | K1: Completion_Percentage | L1: Evidence_Required | M1: Closure_Notes
A2: ACT-001 | B2: R-001 | C2: GA-004 | D2: Threat intelligence review process is not formalized | E2: Define approved intelligence sources, monthly review cadence and decision log. | F2: IT Security | G2: Medium | H2: 46213 | I2: 2026-09-30 | J2: Open | K2: 0 | L2: Threat intelligence review log
A3: ACT-002 | B3: R-002 | C3: GA-005 | D3: Asset inventory does not fully cover SaaS/information assets | E3: Complete discovery, assign owners and establish quarterly review. | F3: IT Operations | G3: High | H3: 46213 | I3: 2026-09-20 | J3: Open | K3: 0 | L3: Updated asset register and review record
A4: ACT-003 | B4: R-003 | C4: GA-007 | D4: Information labeling is inconsistent | E4: Refresh classification guidance and perform sample compliance checks. | F4: Information Security | G4: Medium | H4: 46213 | I4: 2026-09-25 | J4: Open | K4: 0 | L4: Classification compliance check
A5: ACT-004 | B5: R-004 | C5: GA-012 | D5: Quarterly access recertification is incomplete | E5: Complete certification for all critical applications and document exceptions. | F5: IT Security | G5: High | H5: 46213 | I5: 2026-09-15 | J5: In Progress | K5: 50 | L5: Signed access certification report
A6: ACT-005 | B6: R-005 | C6: GA-015 | D6: Cloud exit planning is inconsistent | E6: Create exit checklist, data return/deletion requirements and ownership matrix. | F6: IT Operations | G6: Medium | H6: 46213 | I6: 2026-10-10 | J6: Open | K6: 0 | L6: Approved cloud exit plan
A7: ACT-006 | B7: R-006 | C7: GA-017 | D7: Incident severity is not consistently recorded | E7: Make severity classification mandatory in incident workflow. | F7: SOC / IT Security | G7: Medium | H7: 46213 | I7: 2026-09-10 | J7: In Progress | K7: 40 | L7: Updated incident workflow and sample tickets
A8: ACT-007 | B8: R-007 | C8: GA-022 | D8: PII inventory is incomplete for some SaaS tools | E8: Complete PII discovery, ownership mapping and processing register updates. | F8: Privacy / Legal | G8: High | H8: 46213 | I8: 2026-09-30 | J8: Open | K8: 0 | L8: Updated PII inventory
A9: ACT-008 | B9: R-008 | C9: GA-023 | D9: Independent security review has not been performed | E9: Schedule independent review, record findings and assign corrective actions. | F9: CISO / Management | G9: High | H9: 46213 | I9: 2026-10-15 | J9: Open | K9: 0 | L9: Independent review report
A10: ACT-009 | B10: R-009 | C10: GA-028 | D10: Contractor endpoint compliance visibility is incomplete | E10: Extend endpoint compliance monitoring to contractor devices. | F10: IT Operations | G10: High | H10: 46213 | I10: 2026-09-30 | J10: Open | K10: 0 | L10: Endpoint compliance report
A11: ACT-010 | B11: R-010 | C11: GA-034 | D11: Privileged access recertification is incomplete | E11: Complete quarterly privileged access certification and exception review. | F11: IT Security | G11: High | H11: 46213 | I11: 2026-09-15 | J11: In Progress | K11: 50 | L11: Privileged access review report
A12: ACT-011 | B12: R-011 | C12: GA-035 | D12: MFA is not universal for legacy applications | E12: Implement MFA for remaining legacy applications using approved compensating controls where necessary. | F12: IT Security | G12: High | H12: 46213 | I12: 2026-10-01 | J12: Open | K12: 0 | L12: MFA coverage report
A13: ACT-012 | B13: R-012 | C13: GA-037 | D13: High-severity vulnerability remediation exceeds SLA | E13: Escalate overdue vulnerabilities, assign owners and document approved exceptions. | F13: IT Operations | G13: Critical | H13: 46213 | I13: 2026-08-31 | J13: In Progress | K13: 60 | L13: Vulnerability remediation report
A14: ACT-013 | B14: R-013 | C14: GA-040 | D14: Centralized monitoring is missing for several critical systems | E14: Implement monitoring, alert routing and escalation for critical systems. | F14: IT Security | G14: Critical | H14: 46213 | I14: 2026-11-15 | J14: Open | K14: 0 | L14: Monitoring coverage report and alert test evidence

Sheet Evidence_Index
A1: Evidence_ID | B1: Evidence_Type | C1: Related_Control | D1: Related_Assessment | E1: Description | F1: Owner | G1: Review_Status | H1: Notes
A2: EV-001 | B2: Policy | C2: A.5.1 | D2: GA-001 | E2: Approved information security policy, version history and review record. | F2: Information Security | G2: Available | H2: Simulated evidence reference
A3: EV-002 | B3: RACI | C3: A.5.2 | D3: GA-002 | E3: Information security responsibilities and RACI matrix. | F3: Information Security | G3: Available | H3: Simulated evidence reference
A4: EV-003 | B4: Management Record | C4: A.5.4 | D4: GA-003 | E4: Quarterly security governance meeting minutes. | F4: Management | G4: Available | H4: Simulated evidence reference
A5: EV-004 | B5: Threat Intelligence Record | C5: A.5.7 | D5: GA-004 | E5: Threat source review record and intelligence log. | F5: IT Security | G5: Partial | H5: Formal recurring review not yet established
A6: EV-005 | B6: Asset Register | C6: A.5.9 | D6: GA-005 | E6: Hardware and application asset register. | F6: IT Operations | G6: Partial | H6: SaaS/information ownership incomplete
A7: EV-006 | B7: Classification Policy | C7: A.5.12 | D7: GA-007 | E7: Information classification scheme and samples. | F7: Information Security | G7: Partial | H7: Labeling consistency gap
A8: EV-007 | B8: Access Review | C8: A.5.18 | D8: GA-012 | E8: Quarterly access recertification report. | F8: IT Security | G8: Partial | H8: Coverage incomplete
A9: EV-008 | B9: Supplier Assessment | C9: A.5.19 | D9: GA-013 | E9: Supplier security due diligence record. | F9: Procurement / Security | G9: Partial | H9: Coverage varies by supplier risk
A10: EV-009 | B10: Cloud Assessment | C10: A.5.23 | D10: GA-015 | E10: Cloud provider security assessment. | F10: IT Operations | G10: Partial | H10: Exit planning gap
A11: EV-010 | B11: Incident Plan | C11: A.5.24 | D11: GA-016 | E11: Incident response plan and escalation matrix. | F11: IT Security | G11: Available | H11: Simulated evidence reference
A12: EV-011 | B12: PII Inventory | C12: A.5.34 | D12: GA-022 | E12: PII processing inventory. | F12: Privacy / Legal | G12: Partial | H12: SaaS coverage incomplete
... A21: EV-020 | B21: Monitoring Assessment | C21: A.8.16 | D21: GA-040 | E21: Monitoring coverage assessment. | F21: IT Security | G21: Missing | H21: Centralized monitoring gap

Sheet Lookup_Lists
A1: Assessment_Status | B1: Evidence_Available | C1: Priority | D1: Risk_Treatment | E1: Risk_Status | F1: Remediation_Status | G1: Likelihood | H1: Impact | I1: Risk_Band | K1: Score | L1: Risk Level | M1: Response
A2: Implemented | B2: Yes | C2: Low | D2: Mitigate | E2: Open | F2: Open | G2: 1 | H2: 1 | I2: Low | K2: 1–4 | L2: Low | M2: Routine monitoring
A3: Partially Implemented | B3: Partial | C3: Medium | D3: Accept | E3: In Progress | F3: In Progress | G3: 2 | H3: 2 | I3: Medium | K3: 5–9 | L3: Medium | M3: Planned treatment
A4: Not Implemented | B4: No | C4: High | D4: Transfer | E4: Accepted | F4: Blocked | G4: 3 | H4: 3 | I4: High | K4: 10–16 | L4: High | M4: Priority treatment
A5: Not Applicable | C5: Critical | D5: Avoid | E5: Closed | F5: Completed | G5: 4 | H5: 4 | I5: Critical | K5: 17–25 | L5: Critical | M5: Urgent management attention
F6: Accepted | G6: 5 | H6: 5

Sheet Data_Dictionary
A1: Sheet | B1: Field | C1: Meaning | D1: Expected Values / Format
A2: Control_Master | B2: Control_ID | C2: Unique identifier for selected Annex A control. | D2: A.x.x
A3: Control_Master | B3: Control_Category | C3: One of the four Annex A theme groups used in this project. | D3: Organizational / People / Physical / Technological
A4: Gap_Assessment | B4: Assessment_ID | C4: Unique identifier for an assessment record. | D4: GA-###
A5: Gap_Assessment | B5: Status | C5: Current implementation status based on simulated evidence. | D5: Implemented / Partially Implemented / Not Implemented / Not Applicable
A6: Gap_Assessment | B6: Maturity | C6: Simple portfolio maturity label derived from status. | D6: Defined / Operating; Defined / Partially Operating; Not Established
A7: Gap_Assessment | B7: Evidence_Available | C7: Whether evidence supporting the assessment was available. | D7: Yes / Partial / No
A8: Gap_Assessment | B8: Priority | C8: Remediation priority assigned to the gap. | D8: Low / Medium / High / Critical
A9: Risk_Register | B9: Likelihood | C9: Estimated probability rating for the risk. | D9: 1–5
A10: Risk_Register | B10: Impact | C10: Estimated business impact rating for the risk. | D10: 1–5
A11: Risk_Register | B11: Inherent_Risk_Score | C11: Risk before additional treatment. | D11: Likelihood × Impact
A12: Risk_Register | B12: Residual_Risk_Score | C12: Estimated risk after planned/existing treatment. | D12: Residual Likelihood × Residual Impact
... A14: Remediation_Tracker | B14: Completion_Percentage | C14: Progress against remediation action. | D14: 0–100
